An error occurred during analysis: Invalid comparison between dtype=datetime64[ns, UTC] and Timestamp

TypeError: Invalid comparison between dtype=datetime64[ns, UTC] and Timestamp
Traceback:
File "/home/runner/workspace/app.py", line 85, in <module>
    df = load_and_preprocess_data(df_raw)
         ^^^^^^^^^^^^^^^^^^^^^^^^^^^^^^^^
File "/home/runner/workspace/data_preprocessing.py", line 47, in load_and_preprocess_data
    processed_df = processed_df[processed_df['createdAt'] <= current_date]
                                ^^^^^^^^^^^^^^^^^^^^^^^^^^^^^^^^^^^^^^^^^
File "/home/runner/workspace/.pythonlibs/lib/python3.11/site-packages/pandas/core/ops/common.py", line 76, in new_method
    return method(self, other)
           ^^^^^^^^^^^^^^^^^^^
File "/home/runner/workspace/.pythonlibs/lib/python3.11/site-packages/pandas/core/arraylike.py", line 52, in __le__
    return self._cmp_method(other, operator.le)
           ^^^^^^^^^^^^^^^^^^^^^^^^^^^^^^^^^^^^
File "/home/runner/workspace/.pythonlibs/lib/python3.11/site-packages/pandas/core/series.py", line 6119, in _cmp_method
    res_values = ops.comparison_op(lvalues, rvalues, op)
                 ^^^^^^^^^^^^^^^^^^^^^^^^^^^^^^^^^^^^^^^
File "/home/runner/workspace/.pythonlibs/lib/python3.11/site-packages/pandas/core/ops/array_ops.py", line 330, in comparison_op
    res_values = op(lvalues, rvalues)
                 ^^^^^^^^^^^^^^^^^^^^
File "/home/runner/workspace/.pythonlibs/lib/python3.11/site-packages/pandas/core/ops/common.py", line 76, in new_method
    return method(self, other)
           ^^^^^^^^^^^^^^^^^^^
File "/home/runner/workspace/.pythonlibs/lib/python3.11/site-packages/pandas/core/arraylike.py", line 52, in __le__
    return self._cmp_method(other, operator.le)
           ^^^^^^^^^^^^^^^^^^^^^^^^^^^^^^^^^^^^
File "/home/runner/workspace/.pythonlibs/lib/python3.11/site-packages/pandas/core/arrays/datetimelike.py", line 985, in _cmp_method
    return invalid_comparison(self, other, op)
           ^^^^^^^^^^^^^^^^^^^^^^^^^^^^^^^^^^^
File "/home/runner/workspace/.pythonlibs/lib/python3.11/site-packages/pandas/core/ops/invalid.py", line 40, in invalid_comparison
    raise TypeError(f"Invalid comparison between dtype={left.dtype} and {typ}")